<?xml version="1.0" ?>
<sdf version="1.5">

  <model name="pushbot">
    <pose>0 0 0 0 0 0</pose>
    <static>false</static>

    <!-- Body: Main Chassis -->
    <link name="chassis">
      <pose>0 0 0 0 0 0</pose>
      <inertial>
        <mass>130</mass>
        <!-- for a box: ixx = 0.083 * mass * (y*y + z*z)
                        iyy = 0.083 * mass * (x*x + z*z)
                        izz = 0.083 * mass * (x*x + y*y) -->
        <inertia>
          <ixx>1</ixx>
          <ixy>0</ixy>
          <ixz>0</ixz>
          <iyy>1</iyy>
          <iyz>0</iyz>
          <izz>1</izz>
        </inertia>
      </inertial>
      <collision name="collision">
        <geometry>
          <box>
            <size>0.075 0.065 0.02</size>
          </box>
        </geometry>
      </collision>
      <visual name="chassis">
        <geometry>
          <box>
            <size>0.075 0.065 0.02</size>
          </box>
        </geometry>
      </visual>
    </link>

    <!-- Body: Vertical controller PCB -->
    <link name="top">
      <pose>0 0 0.055 0 0 0</pose>
      <inertial>
        <mass>60</mass>
        <!-- for a box: ixx = 0.083 * mass * (y*y + z*z)
                        iyy = 0.083 * mass * (x*x + z*z)
                        izz = 0.083 * mass * (x*x + y*y) -->
        <inertia>
          <ixx>1</ixx>
          <ixy>0.0</ixy>
          <ixz>0.0</ixz>
          <iyy>1</iyy>
          <iyz>0.0</iyz>
          <izz>1</izz>
        </inertia>
      </inertial>
      <collision name="collision">
        <geometry>
          <box>
            <size>0.01 0.05 0.09</size>
          </box>
        </geometry>
      </collision>
      <visual name="top">
        <geometry>
          <box>
            <size>0.01 0.05 0.09</size>
          </box>
        </geometry>
        <material>
          <ambient>0 0 0 1</ambient>
          <diffuse>0 0 0 1</diffuse>
          <specular>0 0 0 1</specular>
          <emissive>0 1 0.5 1</emissive>
        </material>
      </visual>
    </link>

    <joint name="chassis2top" type="fixed">
      <parent>chassis</parent>
      <child>top</child>
    </joint>

    <!-- Body: Top LED PCB -->
    <link name="led_top">
      <pose> -0.004 0 0.11 0 0 0</pose>
      <collision name="collision">
        <geometry>
          <box>
            <size>0.002 0.05 0.02</size>
          </box>
        </geometry>
      </collision>
      <visual name="led_top">
        <geometry>
          <box>
            <size>0.002 0.05 0.02</size>
          </box>
        </geometry>
      </visual>
    </link>

    <joint name="led_top_joint" type="fixed">
      <parent>top</parent>
      <child>led_top</child>
    </joint>

    <!-- Body: Front Plate -->
    <link name="front">
      <pose> 0.055 0 0.004 0 0 0</pose>
      <inertial>
        <mass>10</mass>
        <inertia>
          <ixx>1</ixx>
          <ixy>0.0</ixy>
          <ixz>0.0</ixz>
          <iyy>1</iyy>
          <iyz>0.0</iyz>
          <izz>1</izz>
        </inertia>
      </inertial>
      <collision name="collision">
        <pose>0 0 0 0 -0.68 0</pose>
        <geometry>
          <box>
            <size>0.001 0.1 0.045</size>
          </box>
        </geometry>
      </collision>
      <visual name="front">
        <pose>0 0 0 0 -0.68 0</pose>
        <geometry>
          <box>
            <size>0.001 0.1 0.045</size>
          </box>
        </geometry>
      </visual>
    </link>

    <joint name="chassis2front" type="fixed">
      <parent>chassis</parent>
      <child>front</child>
    </joint>

    <!-- Back Left Wheel -->
    <link name="back_left_wheel">
      <pose> -0.0175 0.0425 0.003 0 0 0</pose>
      <inertial>
        <mass>25</mass>-->
        <!-- for a solid cylinder, along y-axis: ixx = izz = 0.083 * mass * (3*r*r + l*l)
                                                 iyy = 0.5 * mass * r*r -->
        <inertia>
          <ixx>1</ixx>
          <ixy>0</ixy>
          <ixz>0</ixz>
          <iyy>1</iyy>
          <iyz>0</iyz>
          <izz>1</izz>
        </inertia>
      </inertial>
      <collision name="collision">
        <pose>0 0 0 -1.5707 0 0</pose>
        <geometry>
          <cylinder>
            <radius>0.02</radius>
            <length>0.015</length>
          </cylinder>
        </geometry>
        <surface>
          <friction>
            <ode>
              <mu>1.0</mu>
              <mu2>1.0</mu2>
              <slip1>0.0</slip1>
              <slip2>0.0</slip2>
            </ode>
          </friction>
        </surface>
      </collision>
      <visual name="back_left_wheel">
        <pose>0 0 0 -1.5707 0 0</pose>
        <geometry>
          <cylinder>
            <radius>0.02</radius>
            <length>0.015</length>
          </cylinder>
        </geometry>
        <material>
          <ambient>0.1 0.1 0.1 1</ambient>
          <diffuse>0.1 0.1 0.2 1</diffuse>
          <specular>0 0 0 0</specular>
          <emissive>0 0 0 1</emissive>
        </material>
      </visual>
    </link>

    <joint name="back_left_joint" type="revolute">
      <parent>chassis</parent>
      <child>back_left_wheel</child>
      <axis>
      <xyz>0 1 0</xyz>
      </axis>
    </joint>

    <!-- Back Right Wheel -->
    <link name="back_right_wheel">
      <pose> -0.0175 -0.0425 0.003 0 0 0</pose>
      <inertial>
        <mass>25</mass>
        <!-- for a solid cylinder, along y-axis: ixx = izz = 0.083 * mass * (3*r*r + l*l)
                                                 iyy = 0.5 * mass * r*r -->
        <inertia>
          <ixx>1</ixx>
          <ixy>0</ixy>
          <ixz>0</ixz>
          <iyy>1</iyy>
          <iyz>0</iyz>
          <izz>1</izz>
        </inertia>
      </inertial>
      <collision name="collision">
        <pose>0 0 0 -1.5707 0 0</pose>
        <geometry>
          <cylinder>
            <radius>0.02</radius>
            <length>0.015</length>
          </cylinder>
        </geometry>
        <surface>
          <friction>
            <ode>
              <mu>1.0</mu>
              <mu2>1.0</mu2>
              <slip1>0.0</slip1>
              <slip2>0.0</slip2>
            </ode>
          </friction>
        </surface>
      </collision>
      <visual name="back_right_wheel">
        <pose>0 0 0 -1.5707 0 0</pose>
        <geometry>
          <cylinder>
            <radius>0.02</radius>
            <length>0.015</length>
          </cylinder>
        </geometry>
        <material>
          <ambient>0.1 0.1 0.1 1</ambient>
          <diffuse>0.1 0.1 0.2 1</diffuse>
          <specular>0 0 0 0</specular>
          <emissive>0 0 0 1</emissive>
        </material>
      </visual>
    </link>

    <joint name="back_right_joint" type="revolute">
      <parent>chassis</parent>
      <child>back_right_wheel</child>
      <axis>
      <xyz>0 1 0</xyz>
      </axis>
    </joint>

    <!-- Front Left Wheel -->
    <link name="front_left_wheel">
      <pose> 0.0275 0.0425 0.003 0 0 0</pose>
      <inertial>
        <mass>25</mass>
        <!-- for a solid cylinder, along y-axis: ixx = izz = 0.083 * mass * (3*r*r + l*l)
                                                 iyy = 0.5 * mass * r*r -->
        <inertia>
          <ixx>1</ixx>
          <ixy>0</ixy>
          <ixz>0</ixz>
          <iyy>1</iyy>
          <iyz>0</iyz>
          <izz>1</izz>
        </inertia>
      </inertial>
      <collision name="collision">
        <pose>0 0 0 -1.5707 0 0</pose>
        <geometry>
          <cylinder>
            <radius>0.02</radius>
            <length>0.015</length>
          </cylinder>
        </geometry>
        <surface>
          <friction>
            <ode>
              <mu>1.0</mu>
              <mu2>1.0</mu2>
              <slip1>0.0</slip1>
              <slip2>0.0</slip2>
            </ode>
          </friction>
        </surface>
      </collision>
      <visual name="front_left_wheel">
        <pose>0 0 0 -1.5707 0 0</pose>
        <geometry>
          <cylinder>
            <radius>0.02</radius>
            <length>0.015</length>
          </cylinder>
        </geometry>
        <material>
          <ambient>0.1 0.1 0.1 1</ambient>
          <diffuse>0.1 0.1 0.2 1</diffuse>
          <specular>0 0 0 0</specular>
          <emissive>0 0 0 1</emissive>
        </material>
      </visual>
    </link>

    <joint name="front_left_joint" type="revolute">
      <parent>chassis</parent>
      <child>front_left_wheel</child>
      <axis>
      <xyz>0 1 0</xyz>
      </axis>
    </joint>

    <!-- Front Right Wheel -->
    <link name="front_right_wheel">
      <pose> 0.0275 -0.0425 0.003 0 0 0</pose>
      <inertial>
        <mass>25</mass>
        <!-- for a solid cylinder, along y-axis: ixx = izz = 0.083 * mass * (3*r*r + l*l)
                                                 iyy = 0.5 * mass * r*r -->
        <inertia>
          <ixx>1</ixx>
          <ixy>0</ixy>
          <ixz>0</ixz>
          <iyy>1</iyy>
          <iyz>0</iyz>
          <izz>1</izz>
        </inertia>
      </inertial>
      <collision name="collision">
        <pose>0 0 0 -1.5707 0 0</pose>
        <geometry>
          <cylinder>
            <radius>0.02</radius>
            <length>0.015</length>
          </cylinder>
        </geometry>
        <surface>
          <friction>
            <ode>
              <mu>1.0</mu>
              <mu2>1.0</mu2>
              <slip1>0.0</slip1>
              <slip2>0.0</slip2>
            </ode>
          </friction>
        </surface>
      </collision>
      <visual name="front_right_wheel">
        <pose>0 0 0 -1.5707 0 0</pose>
        <geometry>
          <cylinder>
            <radius>0.02</radius>
            <length>0.015</length>
          </cylinder>
        </geometry>
        <material>
          <ambient>0.1 0.1 0.1 1</ambient>
          <diffuse>0.1 0.1 0.2 1</diffuse>
          <specular>0 0 0 0</specular>
          <emissive>0 0 0 1</emissive>
        </material>
      </visual>
    </link>

    <joint name="front_right_joint" type="revolute">
      <parent>chassis</parent>
      <child>front_right_wheel</child>
      <axis>
      <xyz>0 1 0</xyz>
      </axis>
    </joint>

    <!-- Actuators: Wheel Controllers -->
    <plugin name="generic_controller" filename="libgeneric_controller_plugin.so">
      <controller joint_name="back_left_joint">
        <type>velocity</type>
        <pid>10.0 0.1 0.1</pid>
      </controller>
      <controller joint_name="back_right_joint">
        <type>velocity</type>
        <pid>10.0 0.1 0.1</pid>
      </controller>
      <controller joint_name="front_left_joint">
        <type>velocity</type>
        <pid>10.0 0.1 0.1</pid>
      </controller>
      <controller joint_name="front_right_joint">
        <type>velocity</type>
        <pid>10.0 0.1 0.1</pid>
      </controller>
   </plugin>

    <!-- Sensor: DVS Event Camera -->
    <link name='dvs_camera'>
      <pose>0.015 0 0.08 0 1.5708 0</pose>
      <collision name="collision">
        <geometry>
          <cylinder>
            <radius>0.01</radius>
            <length>0.02</length>
          </cylinder>
        </geometry>
      </collision>
      <visual name="dvs_camera">
        <geometry>
          <cylinder>
            <radius>0.01</radius>
            <length>0.02</length>
          </cylinder>
        </geometry>
        <material>
          <ambient>0.1 0.1 0.1 1</ambient>
          <diffuse>0.1 0.1 0.2 1</diffuse>
          <specular>0 0 0 0</specular>
          <emissive>0 0 0 1</emissive>
        </material>
      </visual>
      <gravity>1</gravity>
      <velocity_decay/>
      <self_collide>0</self_collide>
      <sensor name='sensor' type='camera'>
        <pose frame=''>0 0 0.011 0 -1.5708 0</pose>
        <visualize>1</visualize>
        <camera name='dvs_camera'>
          <horizontal_fov>1.047</horizontal_fov>
          <image>
            <width>128</width>
            <height>128</height>
          </image>
          <clip>
            <near>0.1</near>
            <far>100</far>
          </clip>
        </camera>
        <always_on>1</always_on>
        <update_rate>60</update_rate>
        <plugin name='camera_controller' filename='libgazebo_dvs_plugin.so'>
          <cameraName>dvs</cameraName>
          <robotNamespace>pushbot</robotNamespace>
          <eventThreshold>5</eventThreshold>
          <cameraInfoTopicName>camera_info</cameraInfoTopicName>
        </plugin>
      </sensor>
    </link>

    <joint name='dvs_camera_joint' type='fixed'>
      <parent>top</parent>
      <child>dvs_camera</child>
    </joint>

    <!-- ************************************** -->
    <!-- Elements below require additional work -->
    <!-- ************************************** -->
<!--
    <link name="left_pointer">
      <pose> 0.0475 0.025 0.0125 0 -1.5708 0</pose>
      <visual name="visual">
        <geometry>
          <cylinder>
            <radius>0.0025</radius>
            <length>0.01</length>
          </cylinder>
        </geometry>
      </visual>
      <light name='source' type='spot'>
        <pose>0 0 0 0 0 0</pose>
        <diffuse>1 0 0 1</diffuse>
        <specular>1 0 0 1</specular>
        <attenuation>
          <range>100</range>
          <linear>0.01</linear>
          <constant>0.2</constant>
          <quadratic>0.0</quadratic>
        </attenuation>
        <spot>
          <inner_angle>0.006</inner_angle>
          <outer_angle>0.008</outer_angle>
          <falloff>5</falloff>
        </spot>
        <direction>0 0 1</direction>
      </light>
    </link>

    <joint name="left_pointer_joint" type="fixed">
      <parent>front</parent>
      <child>left_pointer</child>
    </joint>

    <link name="right_pointer">
      <pose> 0.0475 -0.025 0.0125 0 -1.5708 0</pose>
      <visual name="visual">
        <geometry>
          <cylinder>
            <radius>0.0025</radius>
            <length>0.01</length>
          </cylinder>
        </geometry>
      </visual>
      <light name='source' type='spot'>
        <pose>0 0 0 0 0 0</pose>
        <diffuse>1 0 0 1</diffuse>
        <specular>1 0 0 1</specular>
        <attenuation>
          <range>100</range>
          <linear>0.01</linear>
          <constant>0.2</constant>
          <quadratic>0.0</quadratic>
        </attenuation>
        <spot>
          <inner_angle>0.006</inner_angle>
          <outer_angle>0.008</outer_angle>
          <falloff>5</falloff>
        </spot>
        <direction>0 0 1</direction>
      </light>
    </link>

    <joint name="right_pointer_joint" type="fixed">
      <parent>front</parent>
      <child>right_pointer</child>
    </joint>

    <link name="led_light">
      <pose> -0.004 0 0.122 0 0 0</pose>
      <visual name="visual">
        <geometry>
          <sphere>
            <radius>0.002</radius>
          </sphere>
        </geometry>
        <material>
        <ambient>1 1 1 1</ambient>
        <diffuse>1 1 1 1</diffuse>
        <specular>1 1 1 1</specular>
        <emissive>0 0 0 1</emissive>
      </material>
      </visual>
      <light name='source' type='point'>
        <pose>0 0 0 0 0 0</pose>
        <diffuse>1 0 0 1</diffuse>
        <specular>1 0 0 1</specular>
        <attenuation>
          <range>100</range>
          <linear>0.01</linear>
          <constant>0.2</constant>
          <quadratic>0.0</quadratic>
        </attenuation>
      </light>
    </link>

    <joint name="led_light_joint" type="fixed">
      <parent>led_top</parent>
      <child>led_light</child>
    </joint>

    <plugin name='light_control' filename='libFlashLightPlugin.so'>
      <light>
        <enable>true</enable>
        <id>left_pointer/source</id>
      </light>
      <light>
        <enable>true</enable>
        <id>right_pointer/source</id>
      </light>
      <light>
        <enable>true</enable>
        <id>led_light/source</id>
        <duration>0.1</duration>
        <interval>0.4</interval>
      </light>
    </plugin>
-->

  </model>
</sdf>
